<?xml version="1.0"?>
<robot name="exam_robot">
  <material name="blue"><color rgba="0 0 1 1"/></material>
  <material name="black"><color rgba="0 0 0 1"/></material>
  <material name="red"><color rgba="1 0 0 1"/></material>

  <link name="base_link">
    <visual>
      <geometry><box size="0.4 0.3 0.1"/></geometry>
      <origin xyz="0 0 0" rpy="0 0 0"/>
      <material name="blue"/>
    </visual>
  </link>

  <link name="left_wheel">
    <visual>
      <geometry><cylinder radius="0.08" length="0.04"/></geometry>
      <origin xyz="0 0 0" rpy="0 1.5708 0"/>
      <material name="black"/>
    </visual>
  </link>

  <joint name="left_wheel_joint" type="continuous">
    <parent link="base_link"/>
    <child link="left_wheel"/>
    <origin xyz="0 0.17 0" rpy="0 0 0"/>
    <axis xyz="0 0 1"/>
  </joint>

  <link name="right_wheel">
    <visual>
      <geometry><cylinder radius="0.08" length="0.04"/></geometry>
      <origin xyz="0 0 0" rpy="0 1.5708 0"/>
      <material name="black"/>
    </visual>
  </link>

  <joint name="right_wheel_joint" type="continuous">
    <parent link="base_link"/>
    <child link="right_wheel"/>
    <origin xyz="0 -0.17 0" rpy="0 0 0"/>
    <axis xyz="0 0 1"/>
  </joint>

  <link name="sensor_link">
    <visual>
      <geometry><box size="0.05 0.05 0.05"/></geometry>
      <origin xyz="0 0 0" rpy="0 0 0"/>
      <material name="red"/>
    </visual>
  </link>

  <joint name="sensor_joint" type="fixed">
    <parent link="base_link"/>
    <child link="sensor_link"/>
    <origin xyz="0.2 0 0.08" rpy="0 0 0"/>
  </joint>
</robot>